 Promise.reject(new Error('something bad happened'))
    .then((res) => {
        console.log(res);
        return 456;
    })
    .catch((err) => {
        console.log(err.message);
        return Promise.resolve(123);
    })
    .then((res) => {
        console.log(res);      
    });